<?xml version="1.0"?>

<robot name="Robot1">
  <link name="MiddleBase_link">
    <visual>
      <origin ryp = "0 0 0" xyz = "0 0 0" />
      <geometry>
        <cylinder radius = ".1" length = ".2" />
      </geometry>
      <material name="green"><color rgba="0 1 0 1" />  </material>
    </visual>
  </link>

  <joint name="Waist" type="revolute">
    <parent link="MiddleBase_link" />
    <child link="Spine_link" />
    <origin xyz="0 0 .1" rpy = "0 0 0"/>
    <axis xyz="0 0 1" />
  </joint>


  <link name="Spine_link">
    <visual>
         <origin xyz="0 0 1.5"/>
         <geometry> <box size=".2 .2 3.0" /></geometry>
         <material name="red">  <color rgba="1 0 0 1" /></material>
    </visual>
  </link>

  <joint name="Scapula" type="revolute">
    <parent link="Spine_link" />
    <child link="Shoulder" />
    <origin xyz="0 0 3.0" rpy = "0 0 0"/>
    <axis xyz="0 1 0" />
  </joint>

  <link name="Shoulder">
    <visual>
      <origin xyz="0 0 0.05 "/>
      <geometry>  <box size="2.6 .1 .1" /> </geometry>
      <material name="blue"> <color rgba="0 0 1 1" /> </material>
    </visual>
  </link>

  <joint name="Shoulder_Right_1" type="revolute">
    <parent link="Shoulder" />
    <child link="Upper_right_arm1" />
    <origin xyz="1.2 0 0" rpy = "0 0 0"/>
    <axis xyz="0 0 1" />
  </joint>

  <link name="Upper_right_arm1">
    <visual>
      <origin xyz="0 0 -.1 "/>
      <geometry>  <cylinder radius = ".1" length = ".2" /> </geometry>
      <material name="green"><color rgba="0 1 0 1" />  </material>
    </visual>
  </link>

  <joint name="Shoulder_Left_1" type="revolute">
    <parent link="Shoulder" />
    <child link="Upper_left_arm1" />
    <origin xyz="-1.2 0 0" rpy = "0 0 0"/>
    <axis xyz="0 0 1" />
  </joint>

  <link name="Upper_left_arm1">
    <visual>
      <origin xyz="0 0 -.1 "/>
      <geometry>  <cylinder radius = ".1" length = ".2" /> </geometry>
      <material name="green"><color rgba="0 1 0 1" />  </material>
    </visual>
  </link>

  <joint name="Shoulder_Left_2" type="revolute">
    <parent link="Upper_left_arm1" />
    <child link="Upper_left_arm2" />
    <origin xyz="0 0 -.2" rpy = "0 0 0"/>
    <axis xyz="1 0 0" />
  </joint>

  <link name="Upper_left_arm2">
    <visual>
      <origin xyz="0 0 -.1 " rpy = "0 1.57 0"/>
      <geometry>  <cylinder radius = ".1" length = ".2" /> </geometry>
      <material name="blue"> <color rgba="0 0 1 1" /> </material>
    </visual>
  </link>

  <joint name="Shoulder_Right_2" type="revolute">
    <parent link="Upper_right_arm1" />
    <child link="Upper_right_arm2" />
    <origin xyz="0 0 -.2" rpy = "0 0 0"/>
    <axis xyz="1 0 0" />
  </joint>

  <link name="Upper_right_arm2">
    <visual>
      <origin xyz="0 0 -.1 " rpy = "0 1.57 0"/>
      <geometry>  <cylinder radius = ".1" length = ".2" /> </geometry>
      <material name="blue"> <color rgba="0 0 1 1" /> </material>
    </visual>
  </link>

  <joint name="Shoulder_Left_3" type="revolute">
    <parent link="Upper_left_arm2" />
    <child link="Upper_left_arm3" />
    <origin xyz="0 0 -.2" rpy = "0 0 0"/>
    <axis xyz="0 0 1" />
  </joint>

  <link name="Upper_left_arm3">
    <visual>
      <origin xyz="0 0 -1.0 " rpy = "0 0 0"/>
      <geometry>  <cylinder radius = ".1" length = "2.0" /> </geometry>
      <material name="red"> <color rgba="1 0 0 1" /> </material>
    </visual>
  </link>

  <joint name="Shoulder_Right_3" type="revolute">
    <parent link="Upper_right_arm2" />
    <child link="Upper_right_arm3" />
    <origin xyz="0 0 -.2" rpy = "0 0 0"/>
    <axis xyz="0 0 1" />
  </joint>

  <link name="Upper_right_arm3">
    <visual>
      <origin xyz="0 0 -1.0 " rpy = "0 0 0"/>
      <geometry>  <cylinder radius = ".1" length = "2.0" /> </geometry>
      <material name="red"> <color rgba="1 0 0 1" /> </material>
    </visual>
  </link>

  <joint name="Elbow_Left" type="revolute">
    <parent link="Upper_left_arm3" />
    <child link="Lower_left" />
    <origin xyz="0 0 -2.0" rpy = "0 0 0"/>
    <axis xyz="1 0 0" />
  </joint>

  <link name="Lower_left">
    <visual>
      <origin xyz="0 0 -1.25 " rpy = "0 0 0"/>
      <geometry>  <cylinder radius = ".1" length = "2.5" /> </geometry>
      <material name="green"> <color rgba="0 1 0 1" /> </material>
    </visual>
  </link>

  <joint name="Elbow_Right" type="revolute">
    <parent link="Upper_right_arm3" />
    <child link="Lower_right" />
    <origin xyz="0 0 -2.0" rpy = "0 0 0"/>
    <axis xyz="1 0 0" />
  </joint>

  <link name="Lower_right">
    <visual>
      <origin xyz="0 0 -1.25 " rpy = "0 0 0"/>
      <geometry>  <cylinder radius = ".1" length = "2.5" /> </geometry>
      <material name="green"> <color rgba="0 1 0 1" /> </material>
    </visual>
  </link>


  <link name="eef_right_link" />
  <joint name="eef_right" type="fixed">
    <origin xyz="0 0 -1.25" rpy="0 0 0" />
    <parent link="Lower_right" />
    <child link="eef_right_link" />
    <axis xyz="0 0 0" />
  </joint>

  <link name="eef_left_link" />
  <joint name="eef_left" type="fixed">
    <origin xyz="0 0 -1.25" rpy="0 0 0" />
    <parent link="Lower_left" />
    <child link="eef_left_link" />
    <axis xyz="0 0 0" />
  </joint>
</robot>
